Reports in /Users/gadiauerbach/certora/stellar/reflector/reflector-dao-contract/emv-1-certora-06-Oct--20-19/Reports
Start Sun Oct 06 20:19:44 IDT 2024
[main] ERROR ALWAYS - Encountered exception Can't recover from previous error(s) while running: contract.wat -b 4 -target certora_ballot_id_increasing -buildDirectory .certora_internal/24_10_06_20_19_43_072
java.lang.Exception: Can't recover from previous error(s)
	at java_cup.runtime.lr_parser.report_fatal_error(lr_parser.java:392)
	at java_cup.runtime.lr_parser.unrecovered_syntax_error(lr_parser.java:539)
	at java_cup.runtime.lr_parser.parse(lr_parser.java:731)
	at wasm.WasmEntryPoint.generateWASMProgramFromTextual(WasmEntryPoint.kt:209)
	at wasm.WasmEntryPoint.webAssemblyToTAC(WasmEntryPoint.kt:59)
	at EntryPointKt.handleSorobanFlow(EntryPoint.kt:564)
	at EntryPointKt$main$4.invokeSuspend(EntryPoint.kt:244)
	at kotlin.coroutines.jvm.internal.BaseContinuationImpl.resumeWith(ContinuationImpl.kt:33)
	at kotlinx.coroutines.UndispatchedCoroutine.afterResume(CoroutineContext.kt:270)
	at kotlinx.coroutines.AbstractCoroutine.resumeWith(AbstractCoroutine.kt:102)
	at kotlin.coroutines.jvm.internal.BaseContinuationImpl.resumeWith(ContinuationImpl.kt:46)
	at kotlinx.coroutines.UndispatchedCoroutine.afterResume(CoroutineContext.kt:270)
	at kotlinx.coroutines.AbstractCoroutine.resumeWith(AbstractCoroutine.kt:102)
	at kotlin.coroutines.jvm.internal.BaseContinuationImpl.resumeWith(ContinuationImpl.kt:46)
	at kotlinx.coroutines.UndispatchedCoroutine.afterResume(CoroutineContext.kt:270)
	at kotlinx.coroutines.AbstractCoroutine.resumeWith(AbstractCoroutine.kt:102)
	at kotlin.coroutines.jvm.internal.BaseContinuationImpl.resumeWith(ContinuationImpl.kt:46)
	at kotlinx.coroutines.UndispatchedCoroutine.afterResume(CoroutineContext.kt:270)
	at kotlinx.coroutines.AbstractCoroutine.resumeWith(AbstractCoroutine.kt:102)
	at kotlin.coroutines.jvm.internal.BaseContinuationImpl.resumeWith(ContinuationImpl.kt:46)
	at kotlinx.coroutines.UndispatchedCoroutine.afterResume(CoroutineContext.kt:270)
	at kotlinx.coroutines.AbstractCoroutine.resumeWith(AbstractCoroutine.kt:102)
	at kotlin.coroutines.jvm.internal.BaseContinuationImpl.resumeWith(ContinuationImpl.kt:46)
	at kotlinx.coroutines.DispatchedTask.run(DispatchedTask.kt:106)
	at java.base/java.util.concurrent.ForkJoinTask$RunnableExecuteAction.compute(ForkJoinTask.java:1726)
	at java.base/java.util.concurrent.ForkJoinTask$RunnableExecuteAction.compute(ForkJoinTask.java:1717)
	at java.base/java.util.concurrent.ForkJoinTask$InterruptibleTask.exec(ForkJoinTask.java:1641)
	at java.base/java.util.concurrent.ForkJoinTask.doExec(ForkJoinTask.java:507)
	at java.base/java.util.concurrent.ForkJoinPool$WorkQueue.topLevelExec(ForkJoinPool.java:1491)
	at java.base/java.util.concurrent.ForkJoinPool.scan(ForkJoinPool.java:2073)
	at java.base/java.util.concurrent.ForkJoinPool.runWorker(ForkJoinPool.java:2035)
	at java.base/java.util.concurrent.ForkJoinWorkerThread.run(ForkJoinWorkerThread.java:187)
[main] ERROR ALWAYS - An internal Prover error occurred, please double-check the provided configuration or command-line arguments, and see low-level crash details below:
Done 0m
Event reporter: all events were sent without errors
Reports in file:///Users/gadiauerbach/certora/stellar/reflector/reflector-dao-contract/emv-1-certora-06-Oct--20-19/Reports
Final report in N/A
